Workbook

Sheet Dynamic_Line_Graph
A1: Choice | B1: AREA_NAME | C1: 2014 | D1: 2015 | E1: 2016 | F1: 2017 | G1: 2018 | H1: 2019 | I1: 2020 | J1: 2021 | K1: 2022 | L1: 2023 | M1: 2024 | N1: 2025
A2: 1 | B2: Agincourt North | C2: =IF(VLOOKUP($B2, 'neighbourhood-crime-rates - 432'!$B$2:$N$165, COLUMN(B1), FALSE) = 0, NA(), VLOOKUP($B2, 'neighbourhood-crime-rates - 432'!$B$2:$N$165, COLUMN(B1), FALSE)) -> 13.206551 | D2: =IF(VLOOKUP($B2, 'neighbourhood-crime-rates - 432'!$B$2:$N$165, COLUMN(C1), FALSE) = 0, NA(), VLOOKUP($B2, 'neighbourhood-crime-rates - 432'!$B$2:$N$165, COLUMN(C1), FALSE)) -> 23.388687 | E2: =IF(VLOOKUP($B2, 'neighbourhood-crime-rates - 432'!$B$2:$N$165, COLUMN(D1), FALSE) = 0, NA(), VLOOKUP($B2, 'neighbourhood-crime-rates - 432'!$B$2:$N$165, COLUMN(D1), FALSE)) -> 6.6766815 | F2: =IF(VLOOKUP($B2, 'neighbourhood-crime-rates - 432'!$B$2:$N$165, COLUMN(E1), FALSE) = 0, NA(), VLOOKUP($B2, 'neighbourhood-crime-rates - 432'!$B$2:$N$165, COLUMN(E1), FALSE)) -> #N/A | G2: =IF(VLOOKUP($B2, 'neighbourhood-crime-rates - 432'!$B$2:$N$165, COLUMN(F1), FALSE) = 0, NA(), VLOOKUP($B2, 'neighbourhood-crime-rates - 432'!$B$2:$N$165, COLUMN(F1), FALSE)) -> 3.3395672 | H2: =IF(VLOOKUP($B2, 'neighbourhood-crime-rates - 432'!$B$2:$N$165, COLUMN(G1), FALSE) = 0, NA(), VLOOKUP($B2, 'neighbourhood-crime-rates - 432'!$B$2:$N$165, COLUMN(G1), FALSE)) -> 3.348289 | I2: =IF(VLOOKUP($B2, 'neighbourhood-crime-rates - 432'!$B$2:$N$165, COLUMN(H1), FALSE) = 0, NA(), VLOOKUP($B2, 'neighbourhood-crime-rates - 432'!$B$2:$N$165, COLUMN(H1), FALSE)) -> 3.3796344 | J2: =IF(VLOOKUP($B2, 'neighbourhood-crime-rates - 432'!$B$2:$N$165, COLUMN(I1), FALSE) = 0, NA(), VLOOKUP($B2, 'neighbourhood-crime-rates - 432'!$B$2:$N$165, COLUMN(I1), FALSE)) -> 6.8415833 | ... N2: =IF(VLOOKUP($B2, 'neighbourhood-crime-rates - 432'!$B$2:$N$165, COLUMN(M1), FALSE) = 0, NA(), VLOOKUP($B2, 'neighbourhood-crime-rates - 432'!$B$2:$N$165, COLUMN(M1), FALSE)) -> 16.681124
A3: 2 | B3: Alderwood | C3: =IF(VLOOKUP($B3, 'neighbourhood-crime-rates - 432'!$B$2:$N$165, COLUMN(B2), FALSE) = 0, NA(), VLOOKUP($B3, 'neighbourhood-crime-rates - 432'!$B$2:$N$165, COLUMN(B2), FALSE)) -> 40.342102 | D3: =IF(VLOOKUP($B3, 'neighbourhood-crime-rates - 432'!$B$2:$N$165, COLUMN(C2), FALSE) = 0, NA(), VLOOKUP($B3, 'neighbourhood-crime-rates - 432'!$B$2:$N$165, COLUMN(C2), FALSE)) -> 16.165535 | E3: =IF(VLOOKUP($B3, 'neighbourhood-crime-rates - 432'!$B$2:$N$165, COLUMN(D2), FALSE) = 0, NA(), VLOOKUP($B3, 'neighbourhood-crime-rates - 432'!$B$2:$N$165, COLUMN(D2), FALSE)) -> 24.1507 | F3: =IF(VLOOKUP($B3, 'neighbourhood-crime-rates - 432'!$B$2:$N$165, COLUMN(E2), FALSE) = 0, NA(), VLOOKUP($B3, 'neighbourhood-crime-rates - 432'!$B$2:$N$165, COLUMN(E2), FALSE)) -> 31.675642 | G3: =IF(VLOOKUP($B3, 'neighbourhood-crime-rates - 432'!$B$2:$N$165, COLUMN(F2), FALSE) = 0, NA(), VLOOKUP($B3, 'neighbourhood-crime-rates - 432'!$B$2:$N$165, COLUMN(F2), FALSE)) -> 69.924637 | H3: =IF(VLOOKUP($B3, 'neighbourhood-crime-rates - 432'!$B$2:$N$165, COLUMN(G2), FALSE) = 0, NA(), VLOOKUP($B3, 'neighbourhood-crime-rates - 432'!$B$2:$N$165, COLUMN(G2), FALSE)) -> 38.293636 | I3: =IF(VLOOKUP($B3, 'neighbourhood-crime-rates - 432'!$B$2:$N$165, COLUMN(H2), FALSE) = 0, NA(), VLOOKUP($B3, 'neighbourhood-crime-rates - 432'!$B$2:$N$165, COLUMN(H2), FALSE)) -> 60.947739 | J3: =IF(VLOOKUP($B3, 'neighbourhood-crime-rates - 432'!$B$2:$N$165, COLUMN(I2), FALSE) = 0, NA(), VLOOKUP($B3, 'neighbourhood-crime-rates - 432'!$B$2:$N$165, COLUMN(I2), FALSE)) -> #N/A | ... N3: =IF(VLOOKUP($B3, 'neighbourhood-crime-rates - 432'!$B$2:$N$165, COLUMN(M2), FALSE) = 0, NA(), VLOOKUP($B3, 'neighbourhood-crime-rates - 432'!$B$2:$N$165, COLUMN(M2), FALSE)) -> 6.9603953
A4: 3 | B4: St Lawrence-East Bayfront-The Islands | C4: =IF(VLOOKUP($B4, 'neighbourhood-crime-rates - 432'!$B$2:$N$165, COLUMN(B3), FALSE) = 0, NA(), VLOOKUP($B4, 'neighbourhood-crime-rates - 432'!$B$2:$N$165, COLUMN(B3), FALSE)) -> 549.69409 | D4: =IF(VLOOKUP($B4, 'neighbourhood-crime-rates - 432'!$B$2:$N$165, COLUMN(C3), FALSE) = 0, NA(), VLOOKUP($B4, 'neighbourhood-crime-rates - 432'!$B$2:$N$165, COLUMN(C3), FALSE)) -> 420.2041 | E4: =IF(VLOOKUP($B4, 'neighbourhood-crime-rates - 432'!$B$2:$N$165, COLUMN(D3), FALSE) = 0, NA(), VLOOKUP($B4, 'neighbourhood-crime-rates - 432'!$B$2:$N$165, COLUMN(D3), FALSE)) -> 533.5686 | F4: =IF(VLOOKUP($B4, 'neighbourhood-crime-rates - 432'!$B$2:$N$165, COLUMN(E3), FALSE) = 0, NA(), VLOOKUP($B4, 'neighbourhood-crime-rates - 432'!$B$2:$N$165, COLUMN(E3), FALSE)) -> 460.54413 | G4: =IF(VLOOKUP($B4, 'neighbourhood-crime-rates - 432'!$B$2:$N$165, COLUMN(F3), FALSE) = 0, NA(), VLOOKUP($B4, 'neighbourhood-crime-rates - 432'!$B$2:$N$165, COLUMN(F3), FALSE)) -> 540.96655 | H4: =IF(VLOOKUP($B4, 'neighbourhood-crime-rates - 432'!$B$2:$N$165, COLUMN(G3), FALSE) = 0, NA(), VLOOKUP($B4, 'neighbourhood-crime-rates - 432'!$B$2:$N$165, COLUMN(G3), FALSE)) -> 482.13748 | I4: =IF(VLOOKUP($B4, 'neighbourhood-crime-rates - 432'!$B$2:$N$165, COLUMN(H3), FALSE) = 0, NA(), VLOOKUP($B4, 'neighbourhood-crime-rates - 432'!$B$2:$N$165, COLUMN(H3), FALSE)) -> 405.21716 | J4: =IF(VLOOKUP($B4, 'neighbourhood-crime-rates - 432'!$B$2:$N$165, COLUMN(I3), FALSE) = 0, NA(), VLOOKUP($B4, 'neighbourhood-crime-rates - 432'!$B$2:$N$165, COLUMN(I3), FALSE)) -> 395.1973 | ... N4: =IF(VLOOKUP($B4, 'neighbourhood-crime-rates - 432'!$B$2:$N$165, COLUMN(M3), FALSE) = 0, NA(), VLOOKUP($B4, 'neighbourhood-crime-rates - 432'!$B$2:$N$165, COLUMN(M3), FALSE)) -> 275.56232
A5: 4 | B5: Avondale | C5: =IF(VLOOKUP($B5, 'neighbourhood-crime-rates - 432'!$B$2:$N$165, COLUMN(B4), FALSE) = 0, NA(), VLOOKUP($B5, 'neighbourhood-crime-rates - 432'!$B$2:$N$165, COLUMN(B4), FALSE)) -> 23.375408 | D5: =IF(VLOOKUP($B5, 'neighbourhood-crime-rates - 432'!$B$2:$N$165, COLUMN(C4), FALSE) = 0, NA(), VLOOKUP($B5, 'neighbourhood-crime-rates - 432'!$B$2:$N$165, COLUMN(C4), FALSE)) -> 51.698669 | E5: =IF(VLOOKUP($B5, 'neighbourhood-crime-rates - 432'!$B$2:$N$165, COLUMN(D4), FALSE) = 0, NA(), VLOOKUP($B5, 'neighbourhood-crime-rates - 432'!$B$2:$N$165, COLUMN(D4), FALSE)) -> 98.17672 | F5: =IF(VLOOKUP($B5, 'neighbourhood-crime-rates - 432'!$B$2:$N$165, COLUMN(E4), FALSE) = 0, NA(), VLOOKUP($B5, 'neighbourhood-crime-rates - 432'!$B$2:$N$165, COLUMN(E4), FALSE)) -> 138.85995 | G5: =IF(VLOOKUP($B5, 'neighbourhood-crime-rates - 432'!$B$2:$N$165, COLUMN(F4), FALSE) = 0, NA(), VLOOKUP($B5, 'neighbourhood-crime-rates - 432'!$B$2:$N$165, COLUMN(F4), FALSE)) -> 41.152264 | H5: =IF(VLOOKUP($B5, 'neighbourhood-crime-rates - 432'!$B$2:$N$165, COLUMN(G4), FALSE) = 0, NA(), VLOOKUP($B5, 'neighbourhood-crime-rates - 432'!$B$2:$N$165, COLUMN(G4), FALSE)) -> 81.660431 | I5: =IF(VLOOKUP($B5, 'neighbourhood-crime-rates - 432'!$B$2:$N$165, COLUMN(H4), FALSE) = 0, NA(), VLOOKUP($B5, 'neighbourhood-crime-rates - 432'!$B$2:$N$165, COLUMN(H4), FALSE)) -> 251.94063 | J5: =IF(VLOOKUP($B5, 'neighbourhood-crime-rates - 432'!$B$2:$N$165, COLUMN(I4), FALSE) = 0, NA(), VLOOKUP($B5, 'neighbourhood-crime-rates - 432'!$B$2:$N$165, COLUMN(I4), FALSE)) -> 136.87381 | ... N5: =IF(VLOOKUP($B5, 'neighbourhood-crime-rates - 432'!$B$2:$N$165, COLUMN(M4), FALSE) = 0, NA(), VLOOKUP($B5, 'neighbourhood-crime-rates - 432'!$B$2:$N$165, COLUMN(M4), FALSE)) -> 66.557755
A6: 5 | B6: Bayview Village | C6: =IF(VLOOKUP($B6, 'neighbourhood-crime-rates - 432'!$B$2:$N$165, COLUMN(B5), FALSE) = 0, NA(), VLOOKUP($B6, 'neighbourhood-crime-rates - 432'!$B$2:$N$165, COLUMN(B5), FALSE)) -> 38.969261 | D6: =IF(VLOOKUP($B6, 'neighbourhood-crime-rates - 432'!$B$2:$N$165, COLUMN(C5), FALSE) = 0, NA(), VLOOKUP($B6, 'neighbourhood-crime-rates - 432'!$B$2:$N$165, COLUMN(C5), FALSE)) -> 51.977509 | E6: =IF(VLOOKUP($B6, 'neighbourhood-crime-rates - 432'!$B$2:$N$165, COLUMN(D5), FALSE) = 0, NA(), VLOOKUP($B6, 'neighbourhood-crime-rates - 432'!$B$2:$N$165, COLUMN(D5), FALSE)) -> 112.92799 | F6: =IF(VLOOKUP($B6, 'neighbourhood-crime-rates - 432'!$B$2:$N$165, COLUMN(E5), FALSE) = 0, NA(), VLOOKUP($B6, 'neighbourhood-crime-rates - 432'!$B$2:$N$165, COLUMN(E5), FALSE)) -> 53.1185 | G6: =IF(VLOOKUP($B6, 'neighbourhood-crime-rates - 432'!$B$2:$N$165, COLUMN(F5), FALSE) = 0, NA(), VLOOKUP($B6, 'neighbourhood-crime-rates - 432'!$B$2:$N$165, COLUMN(F5), FALSE)) -> 64.977257 | H6: =IF(VLOOKUP($B6, 'neighbourhood-crime-rates - 432'!$B$2:$N$165, COLUMN(G5), FALSE) = 0, NA(), VLOOKUP($B6, 'neighbourhood-crime-rates - 432'!$B$2:$N$165, COLUMN(G5), FALSE)) -> 38.266933 | I6: =IF(VLOOKUP($B6, 'neighbourhood-crime-rates - 432'!$B$2:$N$165, COLUMN(H5), FALSE) = 0, NA(), VLOOKUP($B6, 'neighbourhood-crime-rates - 432'!$B$2:$N$165, COLUMN(H5), FALSE)) -> 193.77396 | J6: =IF(VLOOKUP($B6, 'neighbourhood-crime-rates - 432'!$B$2:$N$165, COLUMN(I5), FALSE) = 0, NA(), VLOOKUP($B6, 'neighbourhood-crime-rates - 432'!$B$2:$N$165, COLUMN(I5), FALSE)) -> 46.121593 | ... N6: =IF(VLOOKUP($B6, 'neighbourhood-crime-rates - 432'!$B$2:$N$165, COLUMN(M5), FALSE) = 0, NA(), VLOOKUP($B6, 'neighbourhood-crime-rates - 432'!$B$2:$N$165, COLUMN(M5), FALSE)) -> 23.30459
A7: 6 | B7: Bendale South | C7: =IF(VLOOKUP($B7, 'neighbourhood-crime-rates - 432'!$B$2:$N$165, COLUMN(B6), FALSE) = 0, NA(), VLOOKUP($B7, 'neighbourhood-crime-rates - 432'!$B$2:$N$165, COLUMN(B6), FALSE)) -> 37.271709 | D7: =IF(VLOOKUP($B7, 'neighbourhood-crime-rates - 432'!$B$2:$N$165, COLUMN(C6), FALSE) = 0, NA(), VLOOKUP($B7, 'neighbourhood-crime-rates - 432'!$B$2:$N$165, COLUMN(C6), FALSE)) -> 18.589088 | E7: =IF(VLOOKUP($B7, 'neighbourhood-crime-rates - 432'!$B$2:$N$165, COLUMN(D6), FALSE) = 0, NA(), VLOOKUP($B7, 'neighbourhood-crime-rates - 432'!$B$2:$N$165, COLUMN(D6), FALSE)) -> 63.42878 | F7: =IF(VLOOKUP($B7, 'neighbourhood-crime-rates - 432'!$B$2:$N$165, COLUMN(E6), FALSE) = 0, NA(), VLOOKUP($B7, 'neighbourhood-crime-rates - 432'!$B$2:$N$165, COLUMN(E6), FALSE)) -> 17.913122 | G7: =IF(VLOOKUP($B7, 'neighbourhood-crime-rates - 432'!$B$2:$N$165, COLUMN(F6), FALSE) = 0, NA(), VLOOKUP($B7, 'neighbourhood-crime-rates - 432'!$B$2:$N$165, COLUMN(F6), FALSE)) -> #N/A | H7: =IF(VLOOKUP($B7, 'neighbourhood-crime-rates - 432'!$B$2:$N$165, COLUMN(G6), FALSE) = 0, NA(), VLOOKUP($B7, 'neighbourhood-crime-rates - 432'!$B$2:$N$165, COLUMN(G6), FALSE)) -> 8.7374401 | I7: =IF(VLOOKUP($B7, 'neighbourhood-crime-rates - 432'!$B$2:$N$165, COLUMN(H6), FALSE) = 0, NA(), VLOOKUP($B7, 'neighbourhood-crime-rates - 432'!$B$2:$N$165, COLUMN(H6), FALSE)) -> #N/A | J7: =IF(VLOOKUP($B7, 'neighbourhood-crime-rates - 432'!$B$2:$N$165, COLUMN(I6), FALSE) = 0, NA(), VLOOKUP($B7, 'neighbourhood-crime-rates - 432'!$B$2:$N$165, COLUMN(I6), FALSE)) -> 26.483051 | ... N7: =IF(VLOOKUP($B7, 'neighbourhood-crime-rates - 432'!$B$2:$N$165, COLUMN(M6), FALSE) = 0, NA(), VLOOKUP($B7, 'neighbourhood-crime-rates - 432'!$B$2:$N$165, COLUMN(M6), FALSE)) -> 8.6662626
A8: 7 | B8: Pelmo Park-Humberlea | C8: =IF(VLOOKUP($B8, 'neighbourhood-crime-rates - 432'!$B$2:$N$165, COLUMN(B7), FALSE) = 0, NA(), VLOOKUP($B8, 'neighbourhood-crime-rates - 432'!$B$2:$N$165, COLUMN(B7), FALSE)) -> 29.694151 | D8: =IF(VLOOKUP($B8, 'neighbourhood-crime-rates - 432'!$B$2:$N$165, COLUMN(C7), FALSE) = 0, NA(), VLOOKUP($B8, 'neighbourhood-crime-rates - 432'!$B$2:$N$165, COLUMN(C7), FALSE)) -> 9.5219955 | E8: =IF(VLOOKUP($B8, 'neighbourhood-crime-rates - 432'!$B$2:$N$165, COLUMN(D7), FALSE) = 0, NA(), VLOOKUP($B8, 'neighbourhood-crime-rates - 432'!$B$2:$N$165, COLUMN(D7), FALSE)) -> 9.1491308 | F8: =IF(VLOOKUP($B8, 'neighbourhood-crime-rates - 432'!$B$2:$N$165, COLUMN(E7), FALSE) = 0, NA(), VLOOKUP($B8, 'neighbourhood-crime-rates - 432'!$B$2:$N$165, COLUMN(E7), FALSE)) -> #N/A | G8: =IF(VLOOKUP($B8, 'neighbourhood-crime-rates - 432'!$B$2:$N$165, COLUMN(F7), FALSE) = 0, NA(), VLOOKUP($B8, 'neighbourhood-crime-rates - 432'!$B$2:$N$165, COLUMN(F7), FALSE)) -> 35.014004 | H8: =IF(VLOOKUP($B8, 'neighbourhood-crime-rates - 432'!$B$2:$N$165, COLUMN(G7), FALSE) = 0, NA(), VLOOKUP($B8, 'neighbourhood-crime-rates - 432'!$B$2:$N$165, COLUMN(G7), FALSE)) -> 8.5873766 | I8: =IF(VLOOKUP($B8, 'neighbourhood-crime-rates - 432'!$B$2:$N$165, COLUMN(H7), FALSE) = 0, NA(), VLOOKUP($B8, 'neighbourhood-crime-rates - 432'!$B$2:$N$165, COLUMN(H7), FALSE)) -> 42.553192 | J8: =IF(VLOOKUP($B8, 'neighbourhood-crime-rates - 432'!$B$2:$N$165, COLUMN(I7), FALSE) = 0, NA(), VLOOKUP($B8, 'neighbourhood-crime-rates - 432'!$B$2:$N$165, COLUMN(I7), FALSE)) -> 25.436663 | ... N8: =IF(VLOOKUP($B8, 'neighbourhood-crime-rates - 432'!$B$2:$N$165, COLUMN(M7), FALSE) = 0, NA(), VLOOKUP($B8, 'neighbourhood-crime-rates - 432'!$B$2:$N$165, COLUMN(M7), FALSE)) -> 39.522568
A9: 8 | B9: York University Heights | C9: =IF(VLOOKUP($B9, 'neighbourhood-crime-rates - 432'!$B$2:$N$165, COLUMN(B8), FALSE) = 0, NA(), VLOOKUP($B9, 'neighbourhood-crime-rates - 432'!$B$2:$N$165, COLUMN(B8), FALSE)) -> 52.045383 | D9: =IF(VLOOKUP($B9, 'neighbourhood-crime-rates - 432'!$B$2:$N$165, COLUMN(C8), FALSE) = 0, NA(), VLOOKUP($B9, 'neighbourhood-crime-rates - 432'!$B$2:$N$165, COLUMN(C8), FALSE)) -> 94.201378 | E9: =IF(VLOOKUP($B9, 'neighbourhood-crime-rates - 432'!$B$2:$N$165, COLUMN(D8), FALSE) = 0, NA(), VLOOKUP($B9, 'neighbourhood-crime-rates - 432'!$B$2:$N$165, COLUMN(D8), FALSE)) -> 87.440102 | F9: =IF(VLOOKUP($B9, 'neighbourhood-crime-rates - 432'!$B$2:$N$165, COLUMN(E8), FALSE) = 0, NA(), VLOOKUP($B9, 'neighbourhood-crime-rates - 432'!$B$2:$N$165, COLUMN(E8), FALSE)) -> 110.13974 | G9: =IF(VLOOKUP($B9, 'neighbourhood-crime-rates - 432'!$B$2:$N$165, COLUMN(F8), FALSE) = 0, NA(), VLOOKUP($B9, 'neighbourhood-crime-rates - 432'!$B$2:$N$165, COLUMN(F8), FALSE)) -> 125.12682 | H9: =IF(VLOOKUP($B9, 'neighbourhood-crime-rates - 432'!$B$2:$N$165, COLUMN(G8), FALSE) = 0, NA(), VLOOKUP($B9, 'neighbourhood-crime-rates - 432'!$B$2:$N$165, COLUMN(G8), FALSE)) -> 60.060059 | I9: =IF(VLOOKUP($B9, 'neighbourhood-crime-rates - 432'!$B$2:$N$165, COLUMN(H8), FALSE) = 0, NA(), VLOOKUP($B9, 'neighbourhood-crime-rates - 432'!$B$2:$N$165, COLUMN(H8), FALSE)) -> 129.61548 | J9: =IF(VLOOKUP($B9, 'neighbourhood-crime-rates - 432'!$B$2:$N$165, COLUMN(I8), FALSE) = 0, NA(), VLOOKUP($B9, 'neighbourhood-crime-rates - 432'!$B$2:$N$165, COLUMN(I8), FALSE)) -> 59.898174 | ... N9: =IF(VLOOKUP($B9, 'neighbourhood-crime-rates - 432'!$B$2:$N$165, COLUMN(M8), FALSE) = 0, NA(), VLOOKUP($B9, 'neighbourhood-crime-rates - 432'!$B$2:$N$165, COLUMN(M8), FALSE)) -> 53.584187
A10: 9 | B10: Mount Pleasant East | C10: =IF(VLOOKUP($B10, 'neighbourhood-crime-rates - 432'!$B$2:$N$165, COLUMN(B9), FALSE) = 0, NA(), VLOOKUP($B10, 'neighbourhood-crime-rates - 432'!$B$2:$N$165, COLUMN(B9), FALSE)) -> 46.819218 | D10: =IF(VLOOKUP($B10, 'neighbourhood-crime-rates - 432'!$B$2:$N$165, COLUMN(C9), FALSE) = 0, NA(), VLOOKUP($B10, 'neighbourhood-crime-rates - 432'!$B$2:$N$165, COLUMN(C9), FALSE)) -> 221.26471 | E10: =IF(VLOOKUP($B10, 'neighbourhood-crime-rates - 432'!$B$2:$N$165, COLUMN(D9), FALSE) = 0, NA(), VLOOKUP($B10, 'neighbourhood-crime-rates - 432'!$B$2:$N$165, COLUMN(D9), FALSE)) -> 115.93531 | F10: =IF(VLOOKUP($B10, 'neighbourhood-crime-rates - 432'!$B$2:$N$165, COLUMN(E9), FALSE) = 0, NA(), VLOOKUP($B10, 'neighbourhood-crime-rates - 432'!$B$2:$N$165, COLUMN(E9), FALSE)) -> 63.591167 | G10: =IF(VLOOKUP($B10, 'neighbourhood-crime-rates - 432'!$B$2:$N$165, COLUMN(F9), FALSE) = 0, NA(), VLOOKUP($B10, 'neighbourhood-crime-rates - 432'!$B$2:$N$165, COLUMN(F9), FALSE)) -> 138.01828 | H10: =IF(VLOOKUP($B10, 'neighbourhood-crime-rates - 432'!$B$2:$N$165, COLUMN(G9), FALSE) = 0, NA(), VLOOKUP($B10, 'neighbourhood-crime-rates - 432'!$B$2:$N$165, COLUMN(G9), FALSE)) -> 109.18285 | I10: =IF(VLOOKUP($B10, 'neighbourhood-crime-rates - 432'!$B$2:$N$165, COLUMN(H9), FALSE) = 0, NA(), VLOOKUP($B10, 'neighbourhood-crime-rates - 432'!$B$2:$N$165, COLUMN(H9), FALSE)) -> 208.50226 | J10: =IF(VLOOKUP($B10, 'neighbourhood-crime-rates - 432'!$B$2:$N$165, COLUMN(I9), FALSE) = 0, NA(), VLOOKUP($B10, 'neighbourhood-crime-rates - 432'!$B$2:$N$165, COLUMN(I9), FALSE)) -> 134.83409 | ... N10: =IF(VLOOKUP($B10, 'neighbourhood-crime-rates - 432'!$B$2:$N$165, COLUMN(M9), FALSE) = 0, NA(), VLOOKUP($B10, 'neighbourhood-crime-rates - 432'!$B$2:$N$165, COLUMN(M9), FALSE)) -> 30.595074
A11: 10 | B11: Wychwood | C11: =IF(VLOOKUP($B11, 'neighbourhood-crime-rates - 432'!$B$2:$N$165, COLUMN(B10), FALSE) = 0, NA(), VLOOKUP($B11, 'neighbourhood-crime-rates - 432'!$B$2:$N$165, COLUMN(B10), FALSE)) -> 80.9002 | D11: =IF(VLOOKUP($B11, 'neighbourhood-crime-rates - 432'!$B$2:$N$165, COLUMN(C10), FALSE) = 0, NA(), VLOOKUP($B11, 'neighbourhood-crime-rates - 432'!$B$2:$N$165, COLUMN(C10), FALSE)) -> 264.49194 | E11: =IF(VLOOKUP($B11, 'neighbourhood-crime-rates - 432'!$B$2:$N$165, COLUMN(D10), FALSE) = 0, NA(), VLOOKUP($B11, 'neighbourhood-crime-rates - 432'!$B$2:$N$165, COLUMN(D10), FALSE)) -> 236.07176 | F11: =IF(VLOOKUP($B11, 'neighbourhood-crime-rates - 432'!$B$2:$N$165, COLUMN(E10), FALSE) = 0, NA(), VLOOKUP($B11, 'neighbourhood-crime-rates - 432'!$B$2:$N$165, COLUMN(E10), FALSE)) -> 134.81631 | G11: =IF(VLOOKUP($B11, 'neighbourhood-crime-rates - 432'!$B$2:$N$165, COLUMN(F10), FALSE) = 0, NA(), VLOOKUP($B11, 'neighbourhood-crime-rates - 432'!$B$2:$N$165, COLUMN(F10), FALSE)) -> 94.174629 | H11: =IF(VLOOKUP($B11, 'neighbourhood-crime-rates - 432'!$B$2:$N$165, COLUMN(G10), FALSE) = 0, NA(), VLOOKUP($B11, 'neighbourhood-crime-rates - 432'!$B$2:$N$165, COLUMN(G10), FALSE)) -> 148.18806 | I11: =IF(VLOOKUP($B11, 'neighbourhood-crime-rates - 432'!$B$2:$N$165, COLUMN(H10), FALSE) = 0, NA(), VLOOKUP($B11, 'neighbourhood-crime-rates - 432'!$B$2:$N$165, COLUMN(H10), FALSE)) -> 136.0822 | J11: =IF(VLOOKUP($B11, 'neighbourhood-crime-rates - 432'!$B$2:$N$165, COLUMN(I10), FALSE) = 0, NA(), VLOOKUP($B11, 'neighbourhood-crime-rates - 432'!$B$2:$N$165, COLUMN(I10), FALSE)) -> 89.772804 | ... N11: =IF(VLOOKUP($B11, 'neighbourhood-crime-rates - 432'!$B$2:$N$165, COLUMN(M10), FALSE) = 0, NA(), VLOOKUP($B11, 'neighbourhood-crime-rates - 432'!$B$2:$N$165, COLUMN(M10), FALSE)) -> 65.040649

Sheet neighbourhood-crime-rates - 432
A1: _id | B1: AREA_NAME | C1: BIKETHEFT_RATE_2014 | D1: BIKETHEFT_RATE_2015 | E1: BIKETHEFT_RATE_2016 | F1: BIKETHEFT_RATE_2017 | G1: BIKETHEFT_RATE_2018 | H1: BIKETHEFT_RATE_2019 | I1: BIKETHEFT_RATE_2020 | J1: BIKETHEFT_RATE_2021 | K1: BIKETHEFT_RATE_2022 | L1: BIKETHEFT_RATE_2023 | M1: BIKETHEFT_RATE_2024 | N1: BIKETHEFT_RATE_2025
A2: 31 | B2: Agincourt North | C2: 13.206551 | D2: 23.388687 | E2: 6.6766815 | G2: 3.3395672 | H2: 3.348289 | I2: 3.3796344 | J2: 6.8415833 | L2: 13.359608 | M2: 16.504374 | N2: 16.681124
A3: 32 | B3: Agincourt South-Malvern West | C3: 4.2285085 | D3: 20.914377 | E3: 12.234411 | F3: 28.145229 | G3: 23.725731 | H3: 11.721955 | I3: 19.433325 | J3: 38.773216 | K3: 22.732439 | L3: 43.742939 | M3: 28.290545 | N3: 14.046423
A4: 137 | B4: Alderwood | C4: 40.342102 | D4: 16.165535 | E4: 24.1507 | F4: 31.675642 | G4: 69.924637 | H4: 38.293636 | I4: 60.947739 | K4: 89.159668 | L4: 14.355441 | M4: 13.969407 | N4: 6.9603953
A5: 63 | B5: Annex | C5: 346.7265 | D5: 388.9603 | E5: 404.19351 | F5: 447.3783 | G5: 411.5481 | H5: 467.04562 | I5: 519.71216 | J5: 380.00494 | K5: 242.55331 | L5: 226.20012 | M5: 266.16272 | N5: 210.46068
A6: 10 | B6: Avondale | C6: 23.375408 | D6: 51.698669 | E6: 98.17672 | F6: 138.85995 | G6: 41.152264 | H6: 81.660431 | I6: 251.94063 | J6: 136.87381 | K6: 179.24716 | L6: 57.146484 | M6: 49.019608 | N6: 66.557755
A7: 111 | B7: Banbury-Don Mills | C7: 10.862874 | D7: 43.410629 | E7: 14.07311 | F7: 34.957703 | G7: 45.055973 | H7: 6.9003587 | I7: 20.769152 | J7: 41.843922 | K7: 27.037989 | L7: 45.19482 | M7: 3.1115813 | N7: 12.271068
A8: 119 | B8: Bathurst Manor | C8: 18.79817 | D8: 31.296946 | E8: 24.464832 | F8: 42.311413 | G8: 53.657665 | H8: 29.514196 | I8: 70.80899 | J8: 29.670069 | K8: 46.876831 | L8: 28.597574 | M8: 11.255557 | N8: 22.677023
A9: 6 | B9: Bay-Cloverhill | C9: 542.70209 | D9: 589.16217 | E9: 631.42822 | F9: 618.73529 | G9: 588.61615 | H9: 372.12448 | I9: 322.17551 | J9: 314.49893 | K9: 335.13406 | L9: 259.0314 | M9: 190.45146 | N9: 236.62253
A10: 133 | B10: Bayview Village | C10: 38.969261 | D10: 51.977509 | E10: 112.92799 | F10: 53.1185 | G10: 64.977257 | H10: 38.266933 | I10: 193.77396 | J10: 46.121593 | K10: 27.648314 | L10: 62.467846 | M10: 27.654867 | N10: 23.30459
A11: 135 | B11: Bayview Woods-Steeles | C11: 15.133172 | D11: 22.914757 | E11: 7.4150972 | F11: 14.862153 | G11: 7.4272132 | H11: 14.905351 | I11: 22.593763 | J11: 7.6161461 | L11: 21.899408 | N11: 21.440823
A12: 114 | B12: Bedford Park-Nortown | C12: 46.685341 | D12: 38.319069 | E12: 83.889099 | F12: 46.14481 | G12: 83.657509 | H12: 83.846893 | I12: 33.881077 | J12: 12.881618 | K12: 25.259968 | L12: 28.510916 | M12: 7.9481778 | N12: 19.837334
A13: 76 | B13: Beechborough-Greenbrook | C13: 15.051174 | D13: 75.688766 | E13: 14.753614 | G13: 14.630578 | H13: 14.632719 | L13: 40.09623 | N13: 37.087402
A14: 49 | B14: Bendale South | C14: 37.271709 | D14: 18.589088 | E14: 63.42878 | F14: 17.913122 | H14: 8.7374401 | J14: 26.483051 | K14: 26.31579 | L14: 17.202822 | N14: 8.6662626
A15: 7 | B15: Bendale-Glen Andrew | C15: 53.645191 | D15: 37.005711 | E15: 20.119713 | F15: 114.78191 | G15: 9.8911972 | H15: 14.73767 | I15: 4.9295082 | J15: 19.871826 | K15: 29.639875 | L15: 48.44257 | M15: 67.004883 | N15: 58.117008
A16: 37 | B16: Birchcliffe-Cliffside | C16: 44.861156 | D16: 80.818962 | E16: 95.944176 | F16: 72.977036 | G16: 33.756699 | H16: 20.828127 | I16: 58.0359 | J16: 45.590187 | K16: 24.417044 | L16: 23.679848 | M16: 30.858246 | N16: 15.44163
A17: 155 | B17: Black Creek | C17: 40.067669 | D17: 40.342464 | E17: 17.851564 | F17: 8.8900738 | G17: 48.558689 | H17: 30.871004 | I17: 13.30318 | J17: 31.350771 | K17: 13.314988 | L17: 21.669411 | M17: 29.880053 | N17: 34.405643
A18: 87 | B18: Blake-Jones | C18: 150 | D18: 188.56065 | E18: 137.91374 | F18: 200.32553 | G18: 74.729111 | H18: 224.38295 | I18: 251.00401 | J18: 240.96385 | K18: 75.481194 | L18: 135.26808 | M18: 157.36594 | N18: 36.607689
A19: 51 | B19: Briar Hill-Belgravia | C19: 155.75269 | D19: 74.860489 | E19: 47.554348 | F19: 46.957806 | G19: 85.916328 | H19: 19.607843 | I19: 84.607872 | J19: 6.5074511 | K19: 32.057446 | L19: 31.154589 | M19: 54.931641 | N19: 30.558611
A20: 112 | B20: Bridle Path-Sunnybrook-York Mills | C20: 32.733223 | D20: 64.913986 | E20: 61.019016 | F20: 60.599941 | G20: 29.892387 | H20: 59.072559 | I20: 107.61104 | J20: 9.778039 | K20: 28.344671 | L20: 72.163086 | M20: 34.788658
A21: 128 | B21: Broadview North | C21: 33.456005 | D21: 75.636604 | E21: 132.78009 | F21: 82.925613 | G21: 8.2637796 | H21: 107.38477 | I21: 292.05606 | J21: 84.695518 | K21: 200.95453 | L21: 89.803246 | M21: 64.344887 | N21: 56.703117
A22: 549236169 | B22: 43.7997900211687] | C22: 43.7997196936734] | D22: [-79.1773311231562 | E22: 43.7993810146754] | F22: [-79.1785137372614 | G22: 43.7992173944364] | H22: [-79.1821057434514 | I22: 43.7987202832209] | J22: [-79.1874141346036 | K22: 43.7979405039558] | L22: [-79.1874848715424 | M22: 43.7981047514415] | N22: [-79.1883188018751 | O22: [-79.1470577866902 | P22: 43.8115537586616] | Q22: [-79.1466753864502 | R22: 43.8113507539368] | S22: [-79.1463517423179 | T22: 43.8111080018763] | U22: [-79.1461315077496 | V22: 43.8108455854488] | W22: [-79.146135853799 | X22: 43.8105936313253] | Y22: [-79.1464075941724 | Z22: 43.8104899061737] | AA22: [-79.1463367916566 | AB22: 43.8102671538783] | AC22: [-79.1460989662784 | AD22: 43.8100753330816] | AE22: [-79.1456899354818 | AF22: 43.8100290687709]]]] | AG22: ""type"": ""MultiPolygon""}"
A23: 123 | B23: Brookhaven-Amesbury | C23: 10.864841 | D23: 32.758244 | E23: 21.841215 | F23: 38.039345 | G23: 32.374683 | H23: 21.494976 | I23: 5.3934522 | J23: 38.008362 | K23: 21.53548 | L23: 26.313019 | M23: 10.358937 | N23: 10.442228
A24: 85 | B24: Cabbagetown-South St.James Town | C24: 560.05511 | D24: 617.92865 | E24: 538.21313 | F24: 413.94156 | G24: 727.15253 | H24: 488.85574 | I24: 410.07617 | J24: 322.55325 | K24: 297.96393 | L24: 246.54048 | M24: 215.86617 | N24: 160.63643
A25: 50 | B25: Caledonia-Fairbank | C25: 29.265438 | D25: 9.7770824 | E25: 48.638134 | F25: 28.904518 | G25: 28.549677 | I25: 37.775051 | J25: 28.481915 | K25: 18.898233 | L25: 83.666451 | M25: 46.099945 | N25: 18.723085
A26: 62 | B26: Casa Loma | C26: 163.81506 | D26: 172.21065 | E26: 132.74336 | F26: 95.768761 | G26: 145.51057 | H26: 160.35109 | I26: 201.22411 | J26: 150.61501 | K26: 48.646019 | L26: 69.632492 | M26: 44.696068 | N26: 80.69841
A27: 29 | B27: Centennial Scarborough | C27: 7.315289 | D27: 14.62309 | E27: 43.68084 | F27: 28.874613 | G27: 42.823494 | H27: 21.241945 | I27: 21.26453 | M27: 13.518994 | N27: 6.8050356
A28: 39 | B28: Church-Wellesley | C28: 499.20581 | D28: 579.27838 | E28: 519.64581 | F28: 640.57654 | G28: 425.41122 | H28: 534.85547 | I28: 470.84235 | J28: 413.91422 | K28: 346.82538 | L28: 374.20206 | M28: 224.30035 | N28: 222.97658
A29: 69 | B29: Clairlea-Birchmount | C29: 98.477386 | D29: 74.808304 | E29: 28.742859 | F29: 60.287964 | G29: 34.906452 | H29: 20.712511 | I29: 13.764625 | J29: 41.375031 | K29: 17.015484 | L29: 26.504108 | M29: 29.274004 | N29: 6.5353069
A30: 120 | B30: Clanton Park | C30: 36.875423 | D30: 30.149542 | E30: 5.8833914 | F30: 28.758772 | G30: 61.697235 | H30: 49.428822 | I30: 59.678818 | J30: 64.505722 | K30: 78.210541 | L30: 44.903458 | M30: 48.104675 | N30: 85.482262
A31: 36 | B31: Cliffcrest | C31: 36.986809 | D31: 12.335019 | E31: 42.735043 | F31: 54.305195 | G31: 5.9541531 | H31: 23.580734 | I31: 29.477655 | J31: 11.846937 | K31: 17.473352 | L31: 16.964487 | M31: 5.533422 | N31: 16.626947
A32: 65 | B32: Corso Italia-Davenport | C32: 90.227654 | D32: 55.4785 | E32: 61.496414 | F32: 82.468559 | G32: 34.458992 | H32: 76.357071 | I32: 112.7634 | J32: 86.206894 | K32: 64.382286 | L32: 126.44001 | M32: 55.74913 | N32: 70.56665
A33: 90 | B33: Danforth | C33: 101.23507 | D33: 111.36985 | E33: 280.89886 | F33: 100.24058 | G33: 239.71234 | H33: 279.74823 | I33: 402.53598 | J33: 672.37164 | K33: 322.22333 | L33: 128.06621 | M33: 154.96368 | N33: 39.043434
A34: 97 | B34: Danforth East York | C34: 28.564899 | D34: 22.829746 | E34: 113.00712 | F34: 44.890858 | G34: 50.091835 | H34: 66.504105 | I34: 116.79644 | J34: 123.11825 | K34: 72.15007 | L34: 21.788866 | M34: 26.877386 | N34: 27.159153
A35: 107 | B35: Don Valley Village | C35: 25.261639 | D35: 25.306389 | E35: 7.1689725 | F35: 14.219694 | G35: 28.162073 | H35: 17.5021 | I35: 21.045248 | J35: 59.97319 | K35: 13.806911 | L35: 23.30304 | M35: 22.649324 | N35: 12.875813
A36: 33 | B36: Dorset Park | C36: 19.988007 | D36: 15.982738 | E36: 11.642799 | F36: 15.41604 | G36: 7.6367941 | H36: 3.8035829 | I36: 11.441648 | J36: 30.725506 | K36: 56.895767 | L36: 55.377117 | M36: 72.411293 | N36: 29.058153
A37: 3 | B37: Dovercourt Village | C37: 213.36079 | D37: 259.22086 | E37: 406.62427 | F37: 348.19974 | G37: 222.43642 | H37: 200.98257 | I37: 241.09094 | J37: 206.32738 | K37: 152.77672 | L37: 286.40338 | M37: 254.64349 | N37: 175.18471
A38: 8 | B38: Downsview | C38: 44.365574 | D38: 25.351755 | E38: 56.739376 | F38: 24.161884 | G38: 52.059231 | H38: 44.508736 | I38: 26.996382 | J38: 31.670626 | K38: 20.081329 | L38: 37.680748 | M38: 35.728642 | N38: 34.699631
